<robot name="nubot" xmlns:xacro="http://www.ros.org/wiki/xacro">
      <link name="base_link">
        <inertial>
          <origin xyz="-0.151427 -0 0.175" rpy="0 -0 0"/>
          <mass value="1.14395" />
          <inertia
            ixx="0.126164"
            ixy="0"
            ixz="0"
            iyy="0.416519"
            iyz="0"
            izz="0.481014"
          />
        </inertial>
        <visual>
          <origin xyz="-0.151427 -0 0.175" rpy="0 -0 0"/>
          <geometry>
            <box size="2.01142 1 0.568726" />
          </geometry>
          <material name="metal1">
             <color rgba="0.5 0.1 0.5 1.0" />
          </material>
        </visual>
        <collision>
          <origin xyz="-0.151427 -0 0.175" rpy="0 -0 0"/>
          <geometry>
            <box size="2.01142 1 0.568726" />
          </geometry>
        </collision>
      </link>

      <link name="base_footprint" />
      <joint name="base_joint" type="fixed">
             <parent link="base_link"/>
             <child link="base_footprint"/>
             <origin xyz="0.0 0.0 -0.15" rpy="0.0 0.0 0.0" />
     </joint>

      <link name="base_laser">
        <inertial>
          <mass value="0.1"/>
          <inertia
            ixx="0.000166667"
            iyy="0.000166667"
            izz="0.000166667"
            ixy="0.0"
            ixz="0.0"
            iyz="0.0"
          />
        </inertial>
        <collision>
          <geometry>
            <box size="0.1 0.1 0.1" />
          </geometry>
        </collision>
        <visual>
          <geometry>
            <box size="0.1 0.1 0.1" />
          </geometry>
          <material name="metal1" />
        </visual>
      </link>

      <link name="left_wheel">
        <inertial>
          <mass value="2.0" />
          <inertia
            ixx="0.145833"
            ixy="0"
            ixz="0"
            iyy="0.145833"
            iyz="0"
            izz="0.125"
          />
        </inertial>
        <visual>
          <geometry>
            <sphere radius="0.3" />
          </geometry>
          <material name="metal1" />
        </visual>
        <collision name='collision'>
          <geometry>
            <sphere radius="0.3" />
          </geometry>
        </collision>
      </link>

      <link name="right_wheel">
        <inertial>
          <mass value="2.0" />
          <inertia
            ixx="0.145833"
            ixy="0"
            ixz="0"
            iyy="0.145833"
            iyz="0"
            izz="0.125"
          />
        </inertial>
        <visual>
          <geometry>
            <sphere radius="0.3" />
          </geometry>
          <material name="metal1" />
        </visual>
        <collision name='collision'>
          <geometry>
            <sphere radius="0.3" />
          </geometry>
        </collision>
      </link>

      <link name='caster'>
        <inertial>
        <origin xyz="-0.957138 -0 -0.125" rpy="0 -0 0" />
          <mass value="1" />
          <inertia
            ixx="0.1"
            ixy="0"
            ixz="0"
            iyy="0.1"
            iyz="0"
            izz="0.1"
          />
        </inertial>
        <visual>
        <origin xyz="-0.957138 -0 -0.125" rpy="0 -0 0" />
          <geometry>
            <sphere radius="0.2" />
          </geometry>
          <material name="metal1" />
        </visual>
        <collision name='collision'>
        <origin xyz="-0.957138 -0 -0.125" rpy="0 -0 0" />
          <geometry>
            <sphere radius="0.2" />
          </geometry>
        </collision>
      </link>

      <joint name="lidar_sensor_joint" type="fixed">
        <origin xyz="0 0 0.5" rpy="0 0 0" />
        <parent link="base_link" />
        <child link="base_laser" />
      </joint>

      <joint name="left_wheel_joint" type="continuous">
        <origin xyz="0.554283 0.625029 -0.025" rpy="-1.5707 0 0" />
        <parent link="base_link" />
        <child link="left_wheel" />
        <axis xyz="0 0 1" />
      </joint>

      <joint name="right_wheel_joint" type="continuous">
        <origin xyz="0.554283 -0.625029 -0.025" rpy="-1.5707 0 0" />
        <parent link="base_link" />
        <child link="right_wheel" />
        <axis xyz="0 0 1" />
      </joint>

      <joint name="caster_wheel" type="fixed">
        <parent link="base_link" />
        <child link="caster" />
      </joint>

      <xacro:include filename="$(find nubot)/urdf/nubot.gazebo.xacro" />
</robot>