<?xml version="1.0" ?>
<!--
  You can echo lidar messages using:
    ign topic -e -t /lidar
-->
<sdf version="1.6">
  <world name="visualize_lidar_world">
  <physics name="1ms" type="ignored">
      <max_step_size>0.001</max_step_size>
      <real_time_factor>1.0</real_time_factor>
    </physics>
    <plugin
      filename="libignition-gazebo-physics-system.so"
      name="ignition::gazebo::systems::Physics">
    </plugin>
-   <plugin
      filename="libignition-gazebo-sensors-system.so"
      name="ignition::gazebo::systems::Sensors">
      <render_engine>ogre2</render_engine>
    </plugin>
    <plugin
      filename="libignition-gazebo-scene-broadcaster-system.so"
      name="ignition::gazebo::systems::SceneBroadcaster">
    </plugin>
   <plugin
    filename="ignition-gazebo-user-commands-system"
    name="ignition::gazebo::systems::UserCommands">
    </plugin>

    <light type="directional" name="sun">
      <cast_shadows>true</cast_shadows>
      <pose>0 0 10 0 0 0</pose>
      <diffuse>0.8 0.8 0.8 1</diffuse>
      <specular>0.2 0.2 0.2 1</specular>
      <attenuation>
        <range>1000</range>
        <constant>0.9</constant>
        <linear>0.01</linear>
        <quadratic>0.001</quadratic>
      </attenuation>
      <direction>-0.5 0.1 -0.9</direction>
    </light>

    <model name="ground_plane">
      <static>true</static>
      <link name="link">
        <collision name="collision">
          <geometry>
            <box>
              <size>100 100 0.1</size>
            </box>
          </geometry>
        </collision>
        <visual name="visual">
          <geometry>
            <box>
              <size>100 100 0.1</size>
            </box>
          </geometry>
          <material>
            <ambient>0.8 0.8 0.8 1</ambient>
            <diffuse>0.8 0.8 0.8 1</diffuse>
            <specular>0.8 0.8 0.8 1</specular>
          </material>
        </visual>
      </link>
    </model>

    <include>
    <uri>
    https://fuel.gazebosim.org/1.0/OpenRobotics/models/Grey Wall
    </uri>
    <name>wall1</name>
    <pose>6 7.5 0 0 0 0</pose>
    </include>

    <include>
    <uri>
    https://fuel.gazebosim.org/1.0/OpenRobotics/models/Grey Wall
    </uri>
    <name>wall2</name>
    <pose>6 -7.5 0 0 0 0</pose>
    </include>

    <include>
    <uri>
    https://fuel.gazebosim.org/1.0/OpenRobotics/models/Grey Wall
    </uri>
    <name>wall3</name>
    <pose>9.75 -3.75 0 0 0 1.57</pose>
    </include>

    <include>
    <uri>
    https://fuel.gazebosim.org/1.0/OpenRobotics/models/Grey Wall
    </uri>
    <name>wall4</name>
    <pose>9.75 3.75 0 0 0 1.57</pose>
    </include>

    <include>
    <uri>
    https://fuel.gazebosim.org/1.0/OpenRobotics/models/Grey Wall
    </uri>
    <name>wall5</name>
    <pose>-1 3.75 0 0 0 1.57</pose>
    </include>

    <include>
    <uri>
    https://fuel.gazebosim.org/1.0/OpenRobotics/models/Grey Wall
    </uri>
    <name>wall6</name>
    <pose>-1 0 0 0 0 1.57</pose>
    </include>

    <include>
    <uri>
    https://fuel.gazebosim.org/1.0/OpenRobotics/models/Grey Wall
    </uri>
    <name>wall7</name>
    <pose>-1 -7.75 0 0 0 0</pose>
    </include>

      <model name="outsideN">
    <static>true</static>
    <link name="link">
      <pose>-20 0 0 0 0 0</pose>
      <collision name="collision">
        <geometry>
          <box>
            <size>0.2 50 2.8</size>
          </box>
        </geometry>
      </collision>
      <visual name="visual">
        <cast_shadows>false</cast_shadows>
        <geometry>
          <box>
            <size>0.2 50 2.8</size>
          </box>
        </geometry>
        <material>
          <script>
            <uri>model://grey_wall/materials/scripts</uri>
            <uri>model://grey_wall/materials/textures</uri>
            <name>vrc/grey_wall</name>
          </script>
        </material>
      </visual>
    </link>
  </model>

      <model name="outsideS">
    <static>true</static>
    <link name="link">
      <pose>20 0 0 0 0 0</pose>
      <collision name="collision">
        <geometry>
          <box>
            <size>0.2 50 2.8</size>
          </box>
        </geometry>
      </collision>
      <visual name="visual">
        <cast_shadows>false</cast_shadows>
        <geometry>
          <box>
            <size>0.2 50 2.8</size>
          </box>
        </geometry>
        <material>
          <script>
            <uri>model://grey_wall/materials/scripts</uri>
            <uri>model://grey_wall/materials/textures</uri>
            <name>vrc/grey_wall</name>
          </script>
        </material>
      </visual>
    </link>
  </model>

      <model name="insideS">
    <static>true</static>
    <link name="link">
      <pose>-12 5 0 0 0 0</pose>
      <collision name="collision">
        <geometry>
          <box>
            <size>0.2 30 2.8</size>
          </box>
        </geometry>
      </collision>
      <visual name="visual">
        <cast_shadows>false</cast_shadows>
        <geometry>
          <box>
            <size>0.2 30 2.8</size>
          </box>
        </geometry>
        <material>
          <script>
            <uri>model://grey_wall/materials/scripts</uri>
            <uri>model://grey_wall/materials/textures</uri>
            <name>vrc/grey_wall</name>
          </script>
        </material>
      </visual>
    </link>
  </model>
      <model name="outsideE">
    <static>true</static>
    <link name="link">
      <pose>0 20 0 0 0 0</pose>
      <collision name="collision">
        <geometry>
          <box>
            <size>50 .2 2.8</size>
          </box>
        </geometry>
      </collision>
      <visual name="visual">
        <cast_shadows>false</cast_shadows>
        <geometry>
          <box>
            <size>50 .2 2.8</size>
          </box>
        </geometry>
        <material>
          <script>
            <uri>model://grey_wall/materials/scripts</uri>
            <uri>model://grey_wall/materials/textures</uri>
            <name>vrc/grey_wall</name>
          </script>
        </material>
      </visual>
    </link>
  </model>

      <model name="outsideW">
    <static>true</static>
    <link name="link">
      <pose>0 -20 0 0 0 0</pose>
      <collision name="collision">
        <geometry>
          <box>
            <size>50 .2 2.8</size>
          </box>
        </geometry>
      </collision>
      <visual name="visual">
        <cast_shadows>false</cast_shadows>
        <geometry>
          <box>
            <size>50 .2 2.8</size>
          </box>
        </geometry>
        <material>
          <script>
            <uri>model://grey_wall/materials/scripts</uri>
            <uri>model://grey_wall/materials/textures</uri>
            <name>vrc/grey_wall</name>
          </script>
        </material>
      </visual>
    </link>
  </model>

    <model name='vehicle_blue'>
      <pose>-4 0 0.325 0 0 0.0</pose>
      <link name='chassis'>
        <pose>-0.151427 -0 0.175 0 -0 0</pose>
        <inertial>
          <mass>1.14395</mass>
          <inertia>
            <ixx>0.126164</ixx>
            <ixy>0</ixy>
            <ixz>0</ixz>
            <iyy>0.416519</iyy>
            <iyz>0</iyz>
            <izz>0.481014</izz>
          </inertia>
        </inertial>
        <visual name='visual'>
          <geometry>
            <box>
              <size>2.01142 1 0.568726</size>
            </box>
          </geometry>
          <material>
            <ambient>0.5 0.5 1.0 1</ambient>
            <diffuse>0.5 0.5 1.0 1</diffuse>
            <specular>0.0 0.0 1.0 1</specular>
          </material>
        </visual>
        <collision name='collision'>
          <geometry>
            <box>
              <size>2.01142 1 0.568726</size>
            </box>
          </geometry>
        </collision>
      </link>

      <link name="lidar_link">
        <pose>0 0 0.5 0 0 0</pose>
        <inertial>
          <mass>0.1</mass>
          <inertia>
            <ixx>0.000166667</ixx>
            <iyy>0.000166667</iyy>
            <izz>0.000166667</izz>
          </inertia>
        </inertial>
        <collision name="collision">
          <geometry>
            <box>
              <size>0.1 0.1 0.1</size>
            </box>
          </geometry>
        </collision>
        <visual name="visual">
          <geometry>
            <box>
              <size>0.1 0.1 0.1</size>
            </box>
          </geometry>
        </visual>
        <sensor name='gpu_lidar' type='gpu_lidar'>
        <pose>0 0 0 0 0 0</pose>
          <topic>lidar</topic>
          <update_rate>10</update_rate>
          <lidar>
            <scan>
              <horizontal>
                <samples>640</samples>
                <resolution>1</resolution>
                <min_angle>-1.396263</min_angle>
                <max_angle>1.396263</max_angle>
              </horizontal>
            </scan>
            <range>
              <min>0.08</min>
              <max>10.0</max>
              <resolution>0.01</resolution>
            </range>
          </lidar>
          <alwaysOn>1</alwaysOn>
          <visualize>true</visualize>
        </sensor>
      </link>

      <link name='left_wheel'>
        <pose>0.554283 0.625029 -0.025 -1.5707 0 0</pose>
        <inertial>
          <mass>2</mass>
          <inertia>
            <ixx>0.145833</ixx>
            <ixy>0</ixy>
            <ixz>0</ixz>
            <iyy>0.145833</iyy>
            <iyz>0</iyz>
            <izz>0.125</izz>
          </inertia>
        </inertial>
        <visual name='visual'>
          <geometry>
            <sphere>
              <radius>0.3</radius>
            </sphere>
          </geometry>
          <material>
            <ambient>0.2 0.2 0.2 1</ambient>
            <diffuse>0.2 0.2 0.2 1</diffuse>
            <specular>0.2 0.2 0.2 1</specular>
          </material>
        </visual>
        <collision name='collision'>
          <geometry>
            <sphere>
              <radius>0.3</radius>
            </sphere>
          </geometry>
        </collision>
      </link>

      <link name='right_wheel'>
        <pose>0.554282 -0.625029 -0.025 -1.5707 0 0</pose>
        <inertial>
          <mass>2</mass>
          <inertia>
            <ixx>0.145833</ixx>
            <ixy>0</ixy>
            <ixz>0</ixz>
            <iyy>0.145833</iyy>
            <iyz>0</iyz>
            <izz>0.125</izz>
          </inertia>
        </inertial>
        <visual name='visual'>
          <geometry>
            <sphere>
              <radius>0.3</radius>
            </sphere>
          </geometry>
          <material>
            <ambient>0.2 0.2 0.2 1</ambient>
            <diffuse>0.2 0.2 0.2 1</diffuse>
            <specular>0.2 0.2 0.2 1</specular>
          </material>
        </visual>
        <collision name='collision'>
          <geometry>
            <sphere>
              <radius>0.3</radius>
            </sphere>
          </geometry>
        </collision>
      </link>

      <link name='caster'>
        <pose>-0.957138 -0 -0.125 0 -0 0</pose>
        <inertial>
          <mass>1</mass>
          <inertia>
            <ixx>0.1</ixx>
            <ixy>0</ixy>
            <ixz>0</ixz>
            <iyy>0.1</iyy>
            <iyz>0</iyz>
            <izz>0.1</izz>
          </inertia>
        </inertial>
        <visual name='visual'>
          <geometry>
            <sphere>
              <radius>0.2</radius>
            </sphere>
          </geometry>
          <material>
            <ambient>0.2 0.2 0.2 1</ambient>
            <diffuse>0.2 0.2 0.2 1</diffuse>
            <specular>0.2 0.2 0.2 1</specular>
          </material>
        </visual>
        <collision name='collision'>
          <geometry>
            <sphere>
              <radius>0.2</radius>
            </sphere>
          </geometry>
        </collision>
      </link>

      <joint name='lidar_sensor_joint' type='fixed'>
        <parent>chassis</parent>
        <child>lidar_link</child>
      </joint>

      <joint name='left_wheel_joint' type='revolute'>
        <parent>chassis</parent>
        <child>left_wheel</child>
        <axis>
          <xyz>0 0 1</xyz>
          <limit>
            <lower>-1.79769e+308</lower>
            <upper>1.79769e+308</upper>
          </limit>
        </axis>
      </joint>

      <joint name='right_wheel_joint' type='revolute'>
        <parent>chassis</parent>
        <child>right_wheel</child>
        <axis>
          <xyz>0 0 1</xyz>
          <limit>
            <lower>-1.79769e+308</lower>
            <upper>1.79769e+308</upper>
          </limit>
        </axis>
      </joint>

      <joint name='caster_wheel' type='ball'>
        <parent>chassis</parent>
        <child>caster</child>
      </joint>

      <plugin
        filename="libignition-gazebo-diff-drive-system.so"
        name="ignition::gazebo::systems::DiffDrive">
        <left_joint>left_wheel_joint</left_joint>
        <right_joint>right_wheel_joint</right_joint>
        <wheel_separation>1.25</wheel_separation>
        <wheel_radius>0.3</wheel_radius>
        <odom_publish_frequency>30</odom_publish_frequency>
      </plugin>
    </model>
  </world>
</sdf>
